[2023-04-23T19:26:01.814-0300] {taskinstance.py:1090} INFO - Dependencies all met for dep_context=non-requeueable deps ti=<TaskInstance: trabajo_practico.FiltrarDatos manual__2023-04-23T22:25:59.756435+00:00 [queued]>
[2023-04-23T19:26:01.817-0300] {taskinstance.py:1090} INFO - Dependencies all met for dep_context=requeueable deps ti=<TaskInstance: trabajo_practico.FiltrarDatos manual__2023-04-23T22:25:59.756435+00:00 [queued]>
[2023-04-23T19:26:01.817-0300] {taskinstance.py:1288} INFO - 
--------------------------------------------------------------------------------
[2023-04-23T19:26:01.817-0300] {taskinstance.py:1289} INFO - Starting attempt 1 of 2
[2023-04-23T19:26:01.817-0300] {taskinstance.py:1290} INFO - 
--------------------------------------------------------------------------------
[2023-04-23T19:26:01.831-0300] {taskinstance.py:1309} INFO - Executing <Task(PythonOperator): FiltrarDatos> on 2023-04-23 22:25:59.756435+00:00
[2023-04-23T19:26:01.833-0300] {standard_task_runner.py:55} INFO - Started process 36986 to run task
[2023-04-23T19:26:01.835-0300] {standard_task_runner.py:82} INFO - Running: ['airflow', 'tasks', 'run', 'trabajo_practico', 'FiltrarDatos', 'manual__2023-04-23T22:25:59.756435+00:00', '--job-id', '64', '--raw', '--subdir', 'DAGS_FOLDER/dag_tp.py', '--cfg-path', '/tmp/tmps4jgq6m7']
[2023-04-23T19:26:01.835-0300] {standard_task_runner.py:83} INFO - Job 64: Subtask FiltrarDatos
[2023-04-23T19:26:01.862-0300] {task_command.py:389} INFO - Running <TaskInstance: trabajo_practico.FiltrarDatos manual__2023-04-23T22:25:59.756435+00:00 [running]> on host pepino-ThinkPad-E15-Gen-2
[2023-04-23T19:26:01.975-0300] {taskinstance.py:1516} INFO - Exporting the following env vars:
AIRFLOW_CTX_DAG_OWNER=airflow
AIRFLOW_CTX_DAG_ID=trabajo_practico
AIRFLOW_CTX_TASK_ID=FiltrarDatos
AIRFLOW_CTX_EXECUTION_DATE=2023-04-23T22:25:59.756435+00:00
AIRFLOW_CTX_TRY_NUMBER=1
AIRFLOW_CTX_DAG_RUN_ID=manual__2023-04-23T22:25:59.756435+00:00
[2023-04-23T19:26:02.047-0300] {taskinstance.py:1776} ERROR - Task failed with exception
Traceback (most recent call last):
  File "/home/pepino/.virtualenvs/apache_airflow/lib/python3.10/site-packages/airflow/operators/python.py", line 175, in execute
    return_value = self.execute_callable()
  File "/home/pepino/.virtualenvs/apache_airflow/lib/python3.10/site-packages/airflow/operators/python.py", line 192, in execute_callable
    return self.python_callable(*self.op_args, **self.op_kwargs)
  File "/home/pepino/Desktop/Maestría Udesa/Segundo Año/Programación Avanzada para grandes volúmenes de datos/airflow/dags/dag_tp.py", line 42, in FiltrarDatos
    return [datos_filtrados1.to_dict(). datos_filtrados2.to_dict()]
AttributeError: 'dict' object has no attribute 'datos_filtrados2'
[2023-04-23T19:26:02.049-0300] {taskinstance.py:1327} INFO - Marking task as UP_FOR_RETRY. dag_id=trabajo_practico, task_id=FiltrarDatos, execution_date=20230423T222559, start_date=20230423T222601, end_date=20230423T222602
[2023-04-23T19:26:02.066-0300] {standard_task_runner.py:100} ERROR - Failed to execute job 64 for task FiltrarDatos ('dict' object has no attribute 'datos_filtrados2'; 36986)
[2023-04-23T19:26:02.087-0300] {local_task_job.py:212} INFO - Task exited with return code 1
[2023-04-23T19:26:02.095-0300] {taskinstance.py:2596} INFO - 0 downstream tasks scheduled from follow-on schedule check
