[2023-04-23T19:26:03.438-0300] {taskinstance.py:1090} INFO - Dependencies all met for dep_context=non-requeueable deps ti=<TaskInstance: trabajo_practico.FiltrarDatos manual__2023-04-23T22:24:59.466033+00:00 [queued]>
[2023-04-23T19:26:03.440-0300] {taskinstance.py:1090} INFO - Dependencies all met for dep_context=requeueable deps ti=<TaskInstance: trabajo_practico.FiltrarDatos manual__2023-04-23T22:24:59.466033+00:00 [queued]>
[2023-04-23T19:26:03.441-0300] {taskinstance.py:1288} INFO - 
--------------------------------------------------------------------------------
[2023-04-23T19:26:03.441-0300] {taskinstance.py:1289} INFO - Starting attempt 2 of 2
[2023-04-23T19:26:03.441-0300] {taskinstance.py:1290} INFO - 
--------------------------------------------------------------------------------
[2023-04-23T19:26:03.454-0300] {taskinstance.py:1309} INFO - Executing <Task(PythonOperator): FiltrarDatos> on 2023-04-23 22:24:59.466033+00:00
[2023-04-23T19:26:03.456-0300] {standard_task_runner.py:55} INFO - Started process 36996 to run task
[2023-04-23T19:26:03.458-0300] {standard_task_runner.py:82} INFO - Running: ['airflow', 'tasks', 'run', 'trabajo_practico', 'FiltrarDatos', 'manual__2023-04-23T22:24:59.466033+00:00', '--job-id', '65', '--raw', '--subdir', 'DAGS_FOLDER/dag_tp.py', '--cfg-path', '/tmp/tmp98cidv40']
[2023-04-23T19:26:03.458-0300] {standard_task_runner.py:83} INFO - Job 65: Subtask FiltrarDatos
[2023-04-23T19:26:03.486-0300] {task_command.py:389} INFO - Running <TaskInstance: trabajo_practico.FiltrarDatos manual__2023-04-23T22:24:59.466033+00:00 [running]> on host pepino-ThinkPad-E15-Gen-2
[2023-04-23T19:26:03.567-0300] {taskinstance.py:1516} INFO - Exporting the following env vars:
AIRFLOW_CTX_DAG_OWNER=airflow
AIRFLOW_CTX_DAG_ID=trabajo_practico
AIRFLOW_CTX_TASK_ID=FiltrarDatos
AIRFLOW_CTX_EXECUTION_DATE=2023-04-23T22:24:59.466033+00:00
AIRFLOW_CTX_TRY_NUMBER=2
AIRFLOW_CTX_DAG_RUN_ID=manual__2023-04-23T22:24:59.466033+00:00
[2023-04-23T19:26:03.638-0300] {taskinstance.py:1776} ERROR - Task failed with exception
Traceback (most recent call last):
  File "/home/pepino/.virtualenvs/apache_airflow/lib/python3.10/site-packages/airflow/operators/python.py", line 175, in execute
    return_value = self.execute_callable()
  File "/home/pepino/.virtualenvs/apache_airflow/lib/python3.10/site-packages/airflow/operators/python.py", line 192, in execute_callable
    return self.python_callable(*self.op_args, **self.op_kwargs)
  File "/home/pepino/Desktop/Maestría Udesa/Segundo Año/Programación Avanzada para grandes volúmenes de datos/airflow/dags/dag_tp.py", line 42, in FiltrarDatos
    return [datos_filtrados1.to_dict(). datos_filtrados2.to_dict()]
AttributeError: 'dict' object has no attribute 'datos_filtrados2'
[2023-04-23T19:26:03.640-0300] {taskinstance.py:1327} INFO - Marking task as FAILED. dag_id=trabajo_practico, task_id=FiltrarDatos, execution_date=20230423T222459, start_date=20230423T222603, end_date=20230423T222603
[2023-04-23T19:26:03.653-0300] {standard_task_runner.py:100} ERROR - Failed to execute job 65 for task FiltrarDatos ('dict' object has no attribute 'datos_filtrados2'; 36996)
[2023-04-23T19:26:03.670-0300] {local_task_job.py:212} INFO - Task exited with return code 1
[2023-04-23T19:26:03.676-0300] {taskinstance.py:2596} INFO - 0 downstream tasks scheduled from follow-on schedule check
